[I 220303 10:26:54 interface:134] b'\r\nAnalysis Almost Complete:\r\n\r\nAnalysis Results:\r\n\r\nPerson Group Created For User\r\n\r\n'
[I 220303 10:26:54 interface:139] b'Traceback (most recent call last):\r\n  File "C:\\Users\\Ceere\\Documents\\Hackathon\\projectcode\\facerecognition.py", line 173, in <module>\r\n    analysis()\r\n  File "C:\\Users\\Ceere\\Documents\\Hackathon\\projectcode\\facerecognition.py", line 171, in analysis\r\n    keys()\r\n  File "C:\\Users\\Ceere\\Documents\\Hackathon\\projectcode\\facerecognition.py", line 54, in keys\r\n    face_client.person_group.create(person_group_id=PERSON_GROUP_ID, name=PERSON_GROUP_ID)\r\n  File "C:\\Users\\Ceere\\AppData\\Local\\Programs\\Python\\Python39\\lib\\site-packages\\azure\\cognitiveservices\\vision\\face\\operations\\_person_group_operations.py", line 117, in create\r\n    request = self._client.put(url, query_parameters, header_parameters, body_content)\r\n  File "C:\\Users\\Ceere\\AppData\\Local\\Programs\\Python\\Python39\\lib\\site-packages\\msrest\\service_client.py", line 181, in put\r\n    request = self._request(\'PUT\', url, params, headers, content, form_content)\r\n  File "C:\\Users\\Ceere\\AppData\\Local\\Programs\\Python\\Python39\\lib\\site-packages\\msrest\\service_client.py", line 108, in _request\r\n    request = ClientRequest(method, self.format_url(url))\r\n  File "C:\\Users\\Ceere\\AppData\\Local\\Programs\\Python\\Python39\\lib\\site-packages\\msrest\\service_client.py", line 155, in format_url\r\n    base = self.config.base_url.format(**kwargs).rstrip(\'/\')\r\nKeyError: \'Endpoint\'\r\n'
[I 220308 13:25:17 interface:134] b'\r\nAnalysis Almost Complete:\r\n\r\nAnalysis Results:\r\n\r\nPerson Group Created For User\r\n\r\n'
[I 220308 13:25:17 interface:139] b'Traceback (most recent call last):\r\n  File "C:\\Users\\Ceere\\Documents\\Hackathon\\projectcode\\facerecognition.py", line 173, in <module>\r\n    analysis()\r\n  File "C:\\Users\\Ceere\\Documents\\Hackathon\\projectcode\\facerecognition.py", line 171, in analysis\r\n    keys()\r\n  File "C:\\Users\\Ceere\\Documents\\Hackathon\\projectcode\\facerecognition.py", line 54, in keys\r\n    face_client.person_group.create(person_group_id=PERSON_GROUP_ID, name=PERSON_GROUP_ID)\r\n  File "C:\\Users\\Ceere\\AppData\\Local\\Programs\\Python\\Python39\\lib\\site-packages\\azure\\cognitiveservices\\vision\\face\\operations\\_person_group_operations.py", line 117, in create\r\n    request = self._client.put(url, query_parameters, header_parameters, body_content)\r\n  File "C:\\Users\\Ceere\\AppData\\Local\\Programs\\Python\\Python39\\lib\\site-packages\\msrest\\service_client.py", line 181, in put\r\n    request = self._request(\'PUT\', url, params, headers, content, form_content)\r\n  File "C:\\Users\\Ceere\\AppData\\Local\\Programs\\Python\\Python39\\lib\\site-packages\\msrest\\service_client.py", line 108, in _request\r\n    request = ClientRequest(method, self.format_url(url))\r\n  File "C:\\Users\\Ceere\\AppData\\Local\\Programs\\Python\\Python39\\lib\\site-packages\\msrest\\service_client.py", line 155, in format_url\r\n    base = self.config.base_url.format(**kwargs).rstrip(\'/\')\r\nKeyError: \'Endpoint\'\r\n'
[I 220308 13:30:18 interface:134] b'\r\nAnalysis Almost Complete:\r\n\r\nAnalysis Results:\r\n\r\nPerson Group Created For User\r\n\r\n'
[I 220308 13:30:18 interface:139] b'Traceback (most recent call last):\r\n  File "C:\\Users\\Ceere\\Documents\\Hackathon\\projectcode\\facerecognition.py", line 173, in <module>\r\n    analysis()\r\n  File "C:\\Users\\Ceere\\Documents\\Hackathon\\projectcode\\facerecognition.py", line 171, in analysis\r\n    keys()\r\n  File "C:\\Users\\Ceere\\Documents\\Hackathon\\projectcode\\facerecognition.py", line 54, in keys\r\n    face_client.person_group.create(person_group_id=PERSON_GROUP_ID, name=PERSON_GROUP_ID)\r\n  File "C:\\Users\\Ceere\\AppData\\Local\\Programs\\Python\\Python39\\lib\\site-packages\\azure\\cognitiveservices\\vision\\face\\operations\\_person_group_operations.py", line 117, in create\r\n    request = self._client.put(url, query_parameters, header_parameters, body_content)\r\n  File "C:\\Users\\Ceere\\AppData\\Local\\Programs\\Python\\Python39\\lib\\site-packages\\msrest\\service_client.py", line 181, in put\r\n    request = self._request(\'PUT\', url, params, headers, content, form_content)\r\n  File "C:\\Users\\Ceere\\AppData\\Local\\Programs\\Python\\Python39\\lib\\site-packages\\msrest\\service_client.py", line 108, in _request\r\n    request = ClientRequest(method, self.format_url(url))\r\n  File "C:\\Users\\Ceere\\AppData\\Local\\Programs\\Python\\Python39\\lib\\site-packages\\msrest\\service_client.py", line 155, in format_url\r\n    base = self.config.base_url.format(**kwargs).rstrip(\'/\')\r\nKeyError: \'Endpoint\'\r\n'
[I 220308 13:38:38 interface:134] b'\r\nAnalysis Almost Complete:\r\n\r\nAnalysis Results:\r\n\r\nPerson Group Created For User\r\n\r\n'
[I 220308 13:38:38 interface:139] b'Traceback (most recent call last):\r\n  File "C:\\Users\\Ceere\\Documents\\Hackathon\\projectcode\\facerecognition.py", line 173, in <module>\r\n    analysis()\r\n  File "C:\\Users\\Ceere\\Documents\\Hackathon\\projectcode\\facerecognition.py", line 171, in analysis\r\n    keys()\r\n  File "C:\\Users\\Ceere\\Documents\\Hackathon\\projectcode\\facerecognition.py", line 54, in keys\r\n    face_client.person_group.create(person_group_id=PERSON_GROUP_ID, name=PERSON_GROUP_ID)\r\n  File "C:\\Users\\Ceere\\AppData\\Local\\Programs\\Python\\Python39\\lib\\site-packages\\azure\\cognitiveservices\\vision\\face\\operations\\_person_group_operations.py", line 121, in create\r\n    raise models.APIErrorException(self._deserialize, response)\r\nazure.cognitiveservices.vision.face.models._models_py3.APIErrorException: (404) Resource not found\r\n'
[I 220308 13:52:57 interface:134] b'\r\nAnalysis Almost Complete:\r\n\r\nAnalysis Results:\r\n\r\nPerson Group Created For User\r\n\r\n'
[I 220308 13:52:57 interface:139] b'Traceback (most recent call last):\r\n  File "C:\\Users\\Ceere\\Documents\\Hackathon\\projectcode\\facerecognition.py", line 173, in <module>\r\n    analysis()\r\n  File "C:\\Users\\Ceere\\Documents\\Hackathon\\projectcode\\facerecognition.py", line 171, in analysis\r\n    keys()\r\n  File "C:\\Users\\Ceere\\Documents\\Hackathon\\projectcode\\facerecognition.py", line 54, in keys\r\n    face_client.person_group.create(person_group_id=PERSON_GROUP_ID, name=PERSON_GROUP_ID)\r\n  File "C:\\Users\\Ceere\\AppData\\Local\\Programs\\Python\\Python39\\lib\\site-packages\\azure\\cognitiveservices\\vision\\face\\operations\\_person_group_operations.py", line 121, in create\r\n    raise models.APIErrorException(self._deserialize, response)\r\nazure.cognitiveservices.vision.face.models._models_py3.APIErrorException: (404) Resource not found\r\n'
[I 220308 13:57:24 interface:139] b"'facerecognition2.py' is not recognized as an internal or external command,\r\noperable program or batch file.\r\n"
[I 220308 13:59:28 interface:139] b"'facerecognition.py' is not recognized as an internal or external command,\r\noperable program or batch file.\r\n"
[I 220308 14:04:02 interface:134] b'Person group: c4f29447-9c27-4254-9f16-974f46a09ccb\r\n'
[I 220308 14:04:02 interface:139] b'Traceback (most recent call last):\r\n  File "C:\\Users\\Ceere\\Documents\\Hackathon\\projectcode\\facerecognition.py", line 86, in <module>\r\n    randomlist_images = random.sample(range(0,i), 4)\r\n  File "C:\\Users\\Ceere\\AppData\\Local\\Programs\\Python\\Python39\\lib\\random.py", line 449, in sample\r\n    raise ValueError("Sample larger than population or is negative")\r\nValueError: Sample larger than population or is negative\r\n'
[I 220308 14:10:35 interface:134] b'Person group: ef7a2dbd-eaa5-4bc5-b9a6-231f5f9d55c6\r\n[13, 11, 6, 8]\r\n[13, 11, 6, 8]\r\n[13, 11, 6, 8]\r\n[13, 11, 6, 8]\r\n\r\nTraining the person group...\r\nTraining status: running.\r\n\r\nTraining status: succeeded.\r\n\r\nIdentifying faces in testimage.jpg\r\nPerson for face ID a9a6072b-5253-4e3f-8da4-572e556ad7ae is identified in testimage.jpg with a confidence of 0.54956.\r\nPerson group: ef7a2dbd-eaa5-4bc5-b9a6-231f5f9d55c6\r\n'
[I 220308 14:10:35 interface:139] b'Traceback (most recent call last):\r\n  File "C:\\Users\\Ceere\\Documents\\Hackathon\\projectcode\\facerecognition.py", line 212, in <module>\r\n    face_client.person_group.create(person_group_id=PERSON_GROUP_ID, name=PERSON_GROUP_ID)\r\n  File "C:\\Users\\Ceere\\AppData\\Local\\Programs\\Python\\Python39\\lib\\site-packages\\azure\\cognitiveservices\\vision\\face\\operations\\_person_group_operations.py", line 121, in create\r\n    raise models.APIErrorException(self._deserialize, response)\r\nazure.cognitiveservices.vision.face.models._models_py3.APIErrorException: (PersonGroupExists) Person group \'ef7a2dbd-eaa5-4bc5-b9a6-231f5f9d55c6\' already exists.\r\n'
[I 220308 14:17:18 interface:134] b'Person group: 5e925254-7a06-43a0-8515-f866b1b319ce\r\n[2, 4, 0, 11]\r\n[2, 4, 0, 11]\r\n[2, 4, 0, 11]\r\n[2, 4, 0, 11]\r\n\r\nTraining the person group...\r\nTraining status: running.\r\n\r\nTraining status: succeeded.\r\n\r\nIdentifying faces in testimage.jpg\r\nPerson for face ID fa72a473-3084-4604-8bde-1e8fe632bc63 is identified in testimage.jpg with a confidence of 0.56626.\r\nPerson group: 5e925254-7a06-43a0-8515-f866b1b319ce\r\n'
[I 220308 14:17:18 interface:139] b'Traceback (most recent call last):\r\n  File "C:\\Users\\Ceere\\Documents\\Hackathon\\projectcode\\facerecognition.py", line 212, in <module>\r\n    face_client.person_group.create(person_group_id=PERSON_GROUP_ID, name=PERSON_GROUP_ID)\r\n  File "C:\\Users\\Ceere\\AppData\\Local\\Programs\\Python\\Python39\\lib\\site-packages\\azure\\cognitiveservices\\vision\\face\\operations\\_person_group_operations.py", line 121, in create\r\n    raise models.APIErrorException(self._deserialize, response)\r\nazure.cognitiveservices.vision.face.models._models_py3.APIErrorException: (PersonGroupExists) Person group \'5e925254-7a06-43a0-8515-f866b1b319ce\' already exists.\r\n'
[I 220308 14:22:36 interface:134] b'Person group: 11558a9e-fbe2-4f19-ab5c-7773751a997e\r\n[8, 13, 5, 4]\r\n[8, 13, 5, 4]\r\n[8, 13, 5, 4]\r\n[8, 13, 5, 4]\r\n\r\nTraining the person group...\r\nTraining status: running.\r\n\r\nTraining status: succeeded.\r\n\r\n'
[I 220308 14:22:36 interface:139] b'Traceback (most recent call last):\r\n  File "C:\\Users\\Ceere\\Documents\\Hackathon\\projectcode\\facerecognition.py", line 160, in <module>\r\n    image = open(test_image_array[0], \'r+b\')\r\nIndexError: list index out of range\r\n'
[I 220308 14:33:56 interface2:134] b'Person group: 8d812365-2f86-426a-bf74-d9c959fb2f94\r\n[11, 14, 5, 6]\r\n[11, 14, 5, 6]\r\n'
[I 220308 14:33:56 interface2:139] b'Traceback (most recent call last):\r\n  File "C:\\Users\\Ceere\\Documents\\Hackathon\\projectcode\\facerecognition.py", line 129, in <module>\r\n    face_client.person_group_person.add_face_from_stream(PERSON_GROUP_ID, janetceere.person_id,k)\r\n  File "C:\\Users\\Ceere\\AppData\\Local\\Programs\\Python\\Python39\\lib\\site-packages\\azure\\cognitiveservices\\vision\\face\\operations\\_person_group_person_operations.py", line 767, in add_face_from_stream\r\n    raise models.APIErrorException(self._deserialize, response)\r\nazure.cognitiveservices.vision.face.models._models_py3.APIErrorException: (InvalidImage) No face detected in the image.\r\n'
[I 220308 14:36:41 interface2:134] b'Person group: 2afa9d97-c2ce-4dc1-b807-9f12d09f4a4f\r\n[10, 2, 4, 8]\r\n[10, 2, 4, 8]\r\n[10, 2, 4, 8]\r\n[10, 2, 4, 8]\r\n\r\nTraining the person group...\r\nTraining status: running.\r\n\r\nTraining status: succeeded.\r\n\r\n'
[I 220308 14:36:41 interface2:139] b'Traceback (most recent call last):\r\n  File "C:\\Users\\Ceere\\Documents\\Hackathon\\projectcode\\facerecognition.py", line 160, in <module>\r\n    image = open(test_image_array[0], \'r+b\')\r\nIndexError: list index out of range\r\n'
[I 220308 14:39:55 interface2:134] b'Person group: 607c7cd1-12e6-4c30-9f55-e40f10d660c1\r\n[9, 1, 0, 8]\r\n[9, 1, 0, 8]\r\n[9, 1, 0, 8]\r\n[9, 1, 0, 8]\r\n\r\nTraining the person group...\r\nTraining status: running.\r\n\r\nTraining status: succeeded.\r\n\r\nIdentifying faces in testimage.png\r\nPerson for face ID f128688d-81bb-448c-a59a-f69ec1543ab2 is identified in testimage.png with a confidence of 0.56151.\r\nPerson group: 607c7cd1-12e6-4c30-9f55-e40f10d660c1\r\n'
[I 220308 14:39:55 interface2:139] b'Traceback (most recent call last):\r\n  File "C:\\Users\\Ceere\\Documents\\Hackathon\\projectcode\\facerecognition.py", line 212, in <module>\r\n    face_client.person_group.create(person_group_id=PERSON_GROUP_ID, name=PERSON_GROUP_ID)\r\n  File "C:\\Users\\Ceere\\AppData\\Local\\Programs\\Python\\Python39\\lib\\site-packages\\azure\\cognitiveservices\\vision\\face\\operations\\_person_group_operations.py", line 121, in create\r\n    raise models.APIErrorException(self._deserialize, response)\r\nazure.cognitiveservices.vision.face.models._models_py3.APIErrorException: (PersonGroupExists) Person group \'607c7cd1-12e6-4c30-9f55-e40f10d660c1\' already exists.\r\n'
[I 220308 14:48:15 interface2:134] b'Person group: 0bd2ea7c-24ce-47d6-b4a2-27917c0900bc\r\n[5, 2, 12, 7]\r\n[5, 2, 12, 7]\r\n'
[I 220308 14:48:15 interface2:139] b'Traceback (most recent call last):\r\n  File "C:\\Users\\Ceere\\Documents\\Hackathon\\projectcode\\facerecognition.py", line 129, in <module>\r\n    face_client.person_group_person.add_face_from_stream(PERSON_GROUP_ID, janetceere.person_id,k)\r\n  File "C:\\Users\\Ceere\\AppData\\Local\\Programs\\Python\\Python39\\lib\\site-packages\\azure\\cognitiveservices\\vision\\face\\operations\\_person_group_person_operations.py", line 767, in add_face_from_stream\r\n    raise models.APIErrorException(self._deserialize, response)\r\nazure.cognitiveservices.vision.face.models._models_py3.APIErrorException: (InvalidImage) No face detected in the image.\r\n'
[I 220308 14:50:59 interface2:134] b'Person group: 319cea13-9881-42fb-ae30-87aea9c608e4\r\n[5, 7, 11, 3]\r\n[5, 7, 11, 3]\r\n[5, 7, 11, 3]\r\n[5, 7, 11, 3]\r\n\r\nTraining the person group...\r\nTraining status: succeeded.\r\n\r\nIdentifying faces in testimage.png\r\nUnidentified person for face ID b06bd3b4-4420-4e3a-8ace-fa5f7342789e in testimage.png.\r\nPerson group: 319cea13-9881-42fb-ae30-87aea9c608e4\r\n'
[I 220308 14:50:59 interface2:139] b'Traceback (most recent call last):\r\n  File "C:\\Users\\Ceere\\Documents\\Hackathon\\projectcode\\facerecognition.py", line 212, in <module>\r\n    face_client.person_group.create(person_group_id=PERSON_GROUP_ID, name=PERSON_GROUP_ID)\r\n  File "C:\\Users\\Ceere\\AppData\\Local\\Programs\\Python\\Python39\\lib\\site-packages\\azure\\cognitiveservices\\vision\\face\\operations\\_person_group_operations.py", line 121, in create\r\n    raise models.APIErrorException(self._deserialize, response)\r\nazure.cognitiveservices.vision.face.models._models_py3.APIErrorException: (PersonGroupExists) Person group \'319cea13-9881-42fb-ae30-87aea9c608e4\' already exists.\r\n'
[I 220308 14:56:08 interface2:134] b'Person group: a2224703-5b1a-42c2-a306-b32658614133\r\n[12, 8, 14, 2]\r\n[12, 8, 14, 2]\r\n[12, 8, 14, 2]\r\n'
[I 220308 14:56:08 interface2:139] b'Traceback (most recent call last):\r\n  File "C:\\Users\\Ceere\\Documents\\Hackathon\\projectcode\\facerecognition.py", line 129, in <module>\r\n    face_client.person_group_person.add_face_from_stream(PERSON_GROUP_ID, janetceere.person_id,k)\r\n  File "C:\\Users\\Ceere\\AppData\\Local\\Programs\\Python\\Python39\\lib\\site-packages\\azure\\cognitiveservices\\vision\\face\\operations\\_person_group_person_operations.py", line 767, in add_face_from_stream\r\n    raise models.APIErrorException(self._deserialize, response)\r\nazure.cognitiveservices.vision.face.models._models_py3.APIErrorException: (InvalidImage) No face detected in the image.\r\n'
[I 220308 15:04:36 interface2:134] b'Person group: a066b34f-2968-4f63-8fea-f5a3bc437a75\r\n[10, 11, 13, 6]\r\n[10, 11, 13, 6]\r\n[10, 11, 13, 6]\r\n[10, 11, 13, 6]\r\n\r\nTraining the person group...\r\nTraining status: running.\r\n\r\nTraining status: succeeded.\r\n\r\nIdentifying faces in testimage.png\r\nPerson for face ID 1bffba55-e186-4f85-b034-215da84d03aa is identified in testimage.png with a confidence of 0.75536.\r\nPerson group: a066b34f-2968-4f63-8fea-f5a3bc437a75\r\n'
[I 220308 15:04:36 interface2:139] b'Traceback (most recent call last):\r\n  File "C:\\Users\\Ceere\\Documents\\Hackathon\\projectcode\\facerecognition.py", line 212, in <module>\r\n    face_client.person_group.create(person_group_id=PERSON_GROUP_ID, name=PERSON_GROUP_ID)\r\n  File "C:\\Users\\Ceere\\AppData\\Local\\Programs\\Python\\Python39\\lib\\site-packages\\azure\\cognitiveservices\\vision\\face\\operations\\_person_group_operations.py", line 121, in create\r\n    raise models.APIErrorException(self._deserialize, response)\r\nazure.cognitiveservices.vision.face.models._models_py3.APIErrorException: (PersonGroupExists) Person group \'a066b34f-2968-4f63-8fea-f5a3bc437a75\' already exists.\r\n'
[I 220308 15:12:33 interface2:134] b'Person group: bfe66586-82a9-4384-961b-04955c7518c3\r\n[1, 13, 4, 5]\r\n[1, 13, 4, 5]\r\n[1, 13, 4, 5]\r\n[1, 13, 4, 5]\r\n\r\nTraining the person group...\r\nTraining status: succeeded.\r\n\r\nIdentifying faces in testimage.png\r\nPerson for face ID d18495bd-0ce3-4064-8155-34c69d3d5677 is identified in testimage.png with a confidence of 0.54927.\r\nPerson group: bfe66586-82a9-4384-961b-04955c7518c3\r\n'
[I 220308 15:12:33 interface2:139] b'Traceback (most recent call last):\r\n  File "C:\\Users\\Ceere\\Documents\\Hackathon\\projectcode\\facerecognition.py", line 212, in <module>\r\n    face_client.person_group.create(person_group_id=PERSON_GROUP_ID, name=PERSON_GROUP_ID)\r\n  File "C:\\Users\\Ceere\\AppData\\Local\\Programs\\Python\\Python39\\lib\\site-packages\\azure\\cognitiveservices\\vision\\face\\operations\\_person_group_operations.py", line 121, in create\r\n    raise models.APIErrorException(self._deserialize, response)\r\nazure.cognitiveservices.vision.face.models._models_py3.APIErrorException: (PersonGroupExists) Person group \'bfe66586-82a9-4384-961b-04955c7518c3\' already exists.\r\n'
[I 220308 15:15:38 interface2:134] b'Person group: ab9cf8c8-c742-4fa9-8d86-10d63e24a37a\r\n[3, 4, 13, 5]\r\n[3, 4, 13, 5]\r\n[3, 4, 13, 5]\r\n[3, 4, 13, 5]\r\n\r\nTraining the person group...\r\nTraining status: running.\r\n\r\nTraining status: succeeded.\r\n\r\nIdentifying faces in testimage.png\r\nPerson for face ID 96887e1e-4e4b-445d-a672-3250db3f24a7 is identified in testimage.png with a confidence of 0.64392.\r\nPerson group: ab9cf8c8-c742-4fa9-8d86-10d63e24a37a\r\n'
[I 220308 15:15:38 interface2:139] b'Traceback (most recent call last):\r\n  File "C:\\Users\\Ceere\\Documents\\Hackathon\\projectcode\\facerecognition.py", line 212, in <module>\r\n    face_client.person_group.create(person_group_id=PERSON_GROUP_ID, name=PERSON_GROUP_ID)\r\n  File "C:\\Users\\Ceere\\AppData\\Local\\Programs\\Python\\Python39\\lib\\site-packages\\azure\\cognitiveservices\\vision\\face\\operations\\_person_group_operations.py", line 121, in create\r\n    raise models.APIErrorException(self._deserialize, response)\r\nazure.cognitiveservices.vision.face.models._models_py3.APIErrorException: (PersonGroupExists) Person group \'ab9cf8c8-c742-4fa9-8d86-10d63e24a37a\' already exists.\r\n'
[I 220308 19:40:10 interface2:184] b'Person group: a4f1aef8-fadb-414a-9008-b3c560fa9cf3\r\n[9, 3, 5, 0]\r\n[9, 3, 5, 0]\r\n[9, 3, 5, 0]\r\n[9, 3, 5, 0]\r\n\r\nTraining the person group...\r\nTraining status: succeeded.\r\n\r\n'
[I 220308 19:40:11 interface2:189] b'Traceback (most recent call last):\r\n  File "C:\\Users\\Ceere\\Documents\\Hackathon\\projectcode\\facerecognition.py", line 166, in <module>\r\n    faces = face_client.face.detect_with_stream(image, detection_model=\'detection_03\')\r\n  File "C:\\Users\\Ceere\\AppData\\Local\\Programs\\Python\\Python39\\lib\\site-packages\\azure\\cognitiveservices\\vision\\face\\operations\\_face_operations.py", line 776, in detect_with_stream\r\n    raise models.APIErrorException(self._deserialize, response)\r\nazure.cognitiveservices.vision.face.models._models_py3.APIErrorException: (InvalidImageSize) Image size is too big.\r\n'
[I 220308 19:47:30 interface2:185] b'Person group: 8f0417df-54f9-4c86-96dc-f492b01b7203\r\n[3, 10, 13, 8]\r\n[3, 10, 13, 8]\r\n[3, 10, 13, 8]\r\n[3, 10, 13, 8]\r\n\r\nTraining the person group...\r\nTraining status: succeeded.\r\n\r\n'
[I 220308 19:47:30 interface2:190] b'Traceback (most recent call last):\r\n  File "C:\\Users\\Ceere\\Documents\\Hackathon\\projectcode\\facerecognition.py", line 166, in <module>\r\n    faces = face_client.face.detect_with_stream(image, detection_model=\'detection_03\')\r\n  File "C:\\Users\\Ceere\\AppData\\Local\\Programs\\Python\\Python39\\lib\\site-packages\\azure\\cognitiveservices\\vision\\face\\operations\\_face_operations.py", line 776, in detect_with_stream\r\n    raise models.APIErrorException(self._deserialize, response)\r\nazure.cognitiveservices.vision.face.models._models_py3.APIErrorException: (InvalidImageSize) Image size is too big.\r\n'
[I 220308 21:02:19 interface2:184] b'Person group: 69120799-f91d-4e18-a72f-6b388e330287\r\n[11, 1, 9, 13]\r\n[11, 1, 9, 13]\r\n[11, 1, 9, 13]\r\n[11, 1, 9, 13]\r\n\r\nTraining the person group...\r\nTraining status: succeeded.\r\n\r\n'
[I 220308 21:02:19 interface2:189] b'Traceback (most recent call last):\r\n  File "C:\\Users\\Ceere\\Documents\\Hackathon\\projectcode\\facerecognition.py", line 166, in <module>\r\n    faces = face_client.face.detect_with_stream(image, detection_model=\'detection_03\')\r\n  File "C:\\Users\\Ceere\\AppData\\Local\\Programs\\Python\\Python39\\lib\\site-packages\\azure\\cognitiveservices\\vision\\face\\operations\\_face_operations.py", line 776, in detect_with_stream\r\n    raise models.APIErrorException(self._deserialize, response)\r\nazure.cognitiveservices.vision.face.models._models_py3.APIErrorException: (InvalidImageSize) Image size is too big.\r\n'
[I 220308 21:14:32 interface2:185] b'Person group: de959a0d-4d32-40fd-bc92-110a63d8f960\r\n[12, 3, 1, 14]\r\n[12, 3, 1, 14]\r\n[12, 3, 1, 14]\r\n[12, 3, 1, 14]\r\n'
[I 220308 21:14:32 interface2:190] b'Traceback (most recent call last):\r\n  File "C:\\Users\\Ceere\\Documents\\Hackathon\\projectcode\\facerecognition.py", line 129, in <module>\r\n    face_client.person_group_person.add_face_from_stream(PERSON_GROUP_ID, janetceere.person_id,k)\r\n  File "C:\\Users\\Ceere\\AppData\\Local\\Programs\\Python\\Python39\\lib\\site-packages\\azure\\cognitiveservices\\vision\\face\\operations\\_person_group_person_operations.py", line 767, in add_face_from_stream\r\n    raise models.APIErrorException(self._deserialize, response)\r\nazure.cognitiveservices.vision.face.models._models_py3.APIErrorException: (InvalidImage) No face detected in the image.\r\n'
